Workbook

Sheet CMP_marginals
B1: Units | C1: Location | D1: Direction | E1: Theta_0 | F1: Blocks | G1: Comment
A2: B.20.22.001 | B2: ft2 | C2: 2--19 | D2: 1 | E2: 3375 | F2: 225 | G2: Curtain Walls - Generic Midrise Stick-Built Curtain wall, Config: Monolithic, Lamination: Unknown, Glass Type: Unknown, Details: Aspect ratio = 6:5, Other details Unknown
A3: B.20.22.001 | B3: ft2 | C3: 1 | D3: 1 | E3: 675 | F3: 45 | G3: Curtain Walls - Generic Midrise Stick-Built Curtain wall, Config: Monolithic, Lamination: Unknown, Glass Type: Unknown, Details: Aspect ratio = 6:5, Other details Unknown
A4: B.30.11.011 | B4: ft2 | C4: 2--19 | D4: 1 | E4: 6075 | F4: 61 | G4: Concrete tile roof, tiles secured and compliant with UBC94
A5: B.30.11.011 | B5: ft2 | C5: 1 | D5: 1 | E5: 11250 | F5: 113 | G5: Concrete tile roof, tiles secured and compliant with UBC94
A6: C.10.11.001a | B6: ft | C6: 2--19 | D6: 1 | E6: 1125 | F6: 23 | G6: Wall Partition, Type: Gypsum with metal studs, Full Height, Fixed Below, Fixed Above
A7: C.10.11.001a | B7: ft | C7: 1 | D7: 1 | E7: 112.5 | F7: 3 | G7: Wall Partition, Type: Gypsum with metal studs, Full Height, Fixed Below, Fixed Above
A8: C.30.11.001a | B8: ft | C8: 2--19 | D8: 1 | E8: 170.1 | F8: 2 | G8: Wall Partition, Type: Gypsum + Wallpaper, Full Height, Fixed Below, Fixed Above
A9: C.30.11.001a | B9: ft | C9: 1 | D9: 1 | E9: 243 | F9: 3 | G9: Wall Partition, Type: Gypsum + Wallpaper, Full Height, Fixed Below, Fixed Above
A10: C.30.32.001a | B10: ft2 | C10: all | D10: 1 | E10: 20250 | F10: 81 | G10: Suspended Ceiling, SDC A,B,C, Area (A): A < 250, Vert support only
A11: D.20.21.011a | B11: ft | C11: 2--19 | D11: 1 | E11: 945 | F11: 1 | G11: Cold or Hot Potable - Small Diameter Threaded Steel - (2.5 inches in diameter or less), SDC A or B, PIPING FRAGILITY
A12: D.20.21.011a | B12: ft | C12: 1 | D12: 1 | E12: 675 | F12: 1 | G12: Cold or Hot Potable - Small Diameter Threaded Steel - (2.5 inches in diameter or less), SDC A or B, PIPING FRAGILITY
A13: D.30.41.012a | B13: ft | C13: 2--19 | D13: 1 | E13: 450 | F13: 1 | G13: HVAC Galvanized Sheet Metal Ducting - 6 sq. ft cross sectional area or greater, SDC A or B
A14: D.30.41.012a | B14: ft | C14: 1 | D14: 1 | E14: 1125 | F14: 2 | G14: HVAC Galvanized Sheet Metal Ducting - 6 sq. ft cross sectional area or greater, SDC A or B
A15: D.30.41.011a | B15: ft | C15: 2--19 | D15: 1 | E15: 1687.5 | F15: 2 | G15: HVAC Galvanized Sheet Metal Ducting less than 6 sq. ft in cross sectional area, SDC A or B
A16: D.30.41.011a | B16: ft | C16: 1 | D16: 1 | E16: 112.5 | F16: 1 | G16: HVAC Galvanized Sheet Metal Ducting less than 6 sq. ft in cross sectional area, SDC A or B
A17: D.30.41.031a | B17: ea | C17: 2--19 | D17: 1 | E17: 203 | F17: 21 | G17: HVAC Drops / Diffusers in suspended ceilings - No independent safety wires, SDC A or B
A18: D.30.41.041a | B18: ea | C18: 2--19 | D18: 1 | E18: 113 | F18: 12 | G18: Variable Air Volume (VAV) box with in-line coil, SDC A or B
A19: D.30.41.041a | B19: ea | C19: 1 | D19: 1 | E19: 90 | F19: 9 | G19: Variable Air Volume (VAV) box with in-line coil, SDC A or B
A20: C.30.34.001 | B20: ea | C20: all | D20: 1 | E20: 338 | F20: 338 | G20: Independent Pendant Lighting - non seismic
A21: D.40.11.021a | B21: ft | C21: 2--19 | D21: 1 | E21: 4500 | F21: 5 | G21: Fire Sprinkler Water Piping - Horizontal Mains and Branches - Old Style Victaulic - Thin Wall Steel - No bracing, SDC A or B, PIPING FRAGILITY
A22: D.40.11.021a | B22: ft | C22: 1 | D22: 1 | E22: 4050 | F22: 5 | G22: Fire Sprinkler Water Piping - Horizontal Mains and Branches - Old Style Victaulic - Thin Wall Steel - No bracing, SDC A or B, PIPING FRAGILITY
A23: D.40.11.031a | B23: ea | C23: 2--19 | D23: 1 | E23: 203 | F23: 3 | G23: Fire Sprinkler Drop Standard Threaded Steel - Dropping into unbraced lay-in tile SOFT ceiling - 6 ft. long drop maximum, SDC A or B
A24: D.40.11.031a | B24: ea | C24: 1 | D24: 1 | E24: 180 | F24: 2 | G24: Fire Sprinkler Drop Standard Threaded Steel - Dropping into unbraced lay-in tile SOFT ceiling - 6 ft. long drop maximum, SDC A or B
A25: C.20.11.001b | B25: ea | C25: all | D25: 1 | E25: 3 | F25: 3 | G25: Prefabricated steel stair with steel treads and landings with no seismic joint.
A26: D.50.12.021a | B26: ea | C26: all | D26: 1 | E26: 1 | F26: 1 | G26: Low Voltage Switchgear - Capacity: 100 to <350 Amp - Unanchored equipment that is not vibration isolated - Equipment fragility only
A27: D.10.14.011 | B27: ea | C27: 19 | D27: 1 | E27: 14 | F27: 14 | G27: Traction Elevator – Applies to most California Installations 1976 or later, most western states installations 1982 or later and most other U.S installations 1998 or later.
A28: D.30.31.011a | B28: ea | C28: 19 | D28: 1 | E28: 16 | F28: 16 | G28: Chiller - Capacity: < 100 Ton - Unanchored equipment that is not vibration isolated - Equipment fragility only
A29: D.30.31.021a | B29: ea | C29: 19 | D29: 1 | E29: 16 | F29: 16 | G29: Cooling Tower - Capacity: < 100 Ton - Unanchored equipment that is not vibration isolated - Equipment fragility only
A30: D.30.52.011a | B30: ea | C30: 19 | D30: 1 | E30: 71 | F30: 71 | G30: Air Handling Unit - Capacity: <5000 CFM - Unanchored equipment that is not vibration isolated - Equipment fragility only
A31: D.50.12.013a | B31: ea | C31: 19 | D31: 1 | E31: 17 | F31: 17 | G31: Motor Control Center - Capacity: all - Unanchored equipment that is not vibration isolated - Equipment fragility only
A32: B.10.31.001 | B32: ea | C32: 1--19 | D32: 1 | E32: 40 | F32: =E32 -> 40 | G32: Bolted shear tab gravity connections
A33: B.10.31.011c | B33: ea | C33: 1 | D33: 1 | E33: 36 | F33: =E33 -> 36 | G33: Steel Column Base Plates, Column W > 300 plf
A34: B.10.35.012 | B34: ea | C34: 1--13 | D34: 1 | E34: 8 | F34: 8 | G34: Post-Northridge RBS connection with welded web, beams both sides of column, beam depth >= W30
A35: B.10.35.002 | B35: ea | C35: 1--13 | D35: 1 | E35: 4 | F35: 4 | G35: Post-Northridge RBS connection with welded web, beam one side of column only, beam depth >= W30
A36: B.10.35.011 | B36: ea | C36: 14--19 | D36: 1 | E36: 8 | F36: 8 | G36: Post-Northridge RBS connection with welded web, beams both sides of column, beam depth <= W27
A37: B.10.35.001 | B37: ea | C37: 14--19 | D37: 1 | E37: 4 | F37: 4 | G37: Post-Northridge RBS connection with welded web, beam one side of column only, beam depth <= W27
A38: collapse | B38: ea | C38: 19 | D38: 1 | E38: 1 | G38: Collapsed building
A39: irreparable | B39: ea | C39: 19 | D39: 1 | E39: 1 | G39: Irreparable building

Sheet CMP_marginals_original
B1: Units | C1: Location | D1: Direction | E1: Theta_0 | F1: Blocks | G1: Comment
A2: B.20.22.001 | B2: ft2 | C2: 2--19 | D2: 1 | E2: 3375 | F2: 225 | G2: Curtain Walls - Generic Midrise Stick-Built Curtain wall, Config: Monolithic, Lamination: Unknown, Glass Type: Unknown, Details: Aspect ratio = 6:5, Other details Unknown
A3: B.20.22.001 | B3: ft2 | C3: 1 | D3: 1 | E3: 675 | F3: 45 | G3: Curtain Walls - Generic Midrise Stick-Built Curtain wall, Config: Monolithic, Lamination: Unknown, Glass Type: Unknown, Details: Aspect ratio = 6:5, Other details Unknown
A4: B.30.11.011 | B4: ft2 | C4: 2--19 | D4: 1 | E4: 6075 | F4: 61 | G4: Concrete tile roof, tiles secured and compliant with UBC94
A5: B.30.11.011 | B5: ft2 | C5: 1 | D5: 1 | E5: 11250 | F5: 113 | G5: Concrete tile roof, tiles secured and compliant with UBC94
A6: C.10.11.001a | B6: ft | C6: 2--19 | D6: 1 | E6: 1125 | F6: 23 | G6: Wall Partition, Type: Gypsum with metal studs, Full Height, Fixed Below, Fixed Above
A7: C.10.11.001a | B7: ft | C7: 1 | D7: 1 | E7: 112.5 | F7: 3 | G7: Wall Partition, Type: Gypsum with metal studs, Full Height, Fixed Below, Fixed Above
A8: C.30.11.001a | B8: ft | C8: 2--19 | D8: 1 | E8: 170.1 | F8: 2 | G8: Wall Partition, Type: Gypsum + Wallpaper, Full Height, Fixed Below, Fixed Above
A9: C.30.11.001a | B9: ft | C9: 1 | D9: 1 | E9: 243 | F9: 3 | G9: Wall Partition, Type: Gypsum + Wallpaper, Full Height, Fixed Below, Fixed Above
A10: C.30.27.001 | B10: ft2 | C10: 2--19 | D10: 1 | E10: 16875 | F10: 169 | G10: Raised Access Floor, non seismically rated.
A11: C.30.32.001a | B11: ft2 | C11: all | D11: 1 | E11: 20250 | F11: 81 | G11: Suspended Ceiling, SDC A,B,C, Area (A): A < 250, Vert support only
A12: E.20.22.112a | B12: ea | C12: 2--19 | D12: 1 | E12: 18 | F12: 18 | G12: Vertical Filing Cabinet, 2 drawer, unanchored laterally
A13: E.20.22.102a | B13: ea | C13: 2--19 | D13: 1 | E13: 45 | F13: 45 | G13: Bookcase, 2 shelves, unanchored laterally
A14: D.20.21.011a | B14: ft | C14: 2--19 | D14: 1 | E14: 945 | F14: 1 | G14: Cold or Hot Potable - Small Diameter Threaded Steel - (2.5 inches in diameter or less), SDC A or B, PIPING FRAGILITY
A15: D.20.21.011a | B15: ft | C15: 1 | D15: 1 | E15: 675 | F15: 1 | G15: Cold or Hot Potable - Small Diameter Threaded Steel - (2.5 inches in diameter or less), SDC A or B, PIPING FRAGILITY
A16: D.30.41.012a | B16: ft | C16: 2--19 | D16: 1 | E16: 450 | F16: 1 | G16: HVAC Galvanized Sheet Metal Ducting - 6 sq. ft cross sectional area or greater, SDC A or B
A17: D.30.41.012a | B17: ft | C17: 1 | D17: 1 | E17: 1125 | F17: 2 | G17: HVAC Galvanized Sheet Metal Ducting - 6 sq. ft cross sectional area or greater, SDC A or B
A18: D.30.41.011a | B18: ft | C18: 2--19 | D18: 1 | E18: 1687.5 | F18: 2 | G18: HVAC Galvanized Sheet Metal Ducting less than 6 sq. ft in cross sectional area, SDC A or B
A19: D.30.41.011a | B19: ft | C19: 1 | D19: 1 | E19: 112.5 | F19: 1 | G19: HVAC Galvanized Sheet Metal Ducting less than 6 sq. ft in cross sectional area, SDC A or B
A20: D.30.41.031a | B20: ea | C20: 2--19 | D20: 1 | E20: 203 | F20: 21 | G20: HVAC Drops / Diffusers in suspended ceilings - No independent safety wires, SDC A or B
A21: D.30.41.041a | B21: ea | C21: 2--19 | D21: 1 | E21: 113 | F21: 12 | G21: Variable Air Volume (VAV) box with in-line coil, SDC A or B
A22: D.30.41.041a | B22: ea | C22: 1 | D22: 1 | E22: 90 | F22: 9 | G22: Variable Air Volume (VAV) box with in-line coil, SDC A or B
A23: C.30.34.001 | B23: ea | C23: all | D23: 1 | E23: 338 | F23: 338 | G23: Independent Pendant Lighting - non seismic
A24: D.40.11.021a | B24: ft | C24: 2--19 | D24: 1 | E24: 4500 | F24: 5 | G24: Fire Sprinkler Water Piping - Horizontal Mains and Branches - Old Style Victaulic - Thin Wall Steel - No bracing, SDC A or B, PIPING FRAGILITY
A25: D.40.11.021a | B25: ft | C25: 1 | D25: 1 | E25: 4050 | F25: 5 | G25: Fire Sprinkler Water Piping - Horizontal Mains and Branches - Old Style Victaulic - Thin Wall Steel - No bracing, SDC A or B, PIPING FRAGILITY
A26: D.40.11.031a | B26: ea | C26: 2--19 | D26: 1 | E26: 203 | F26: 3 | G26: Fire Sprinkler Drop Standard Threaded Steel - Dropping into unbraced lay-in tile SOFT ceiling - 6 ft. long drop maximum, SDC A or B
A27: D.40.11.031a | B27: ea | C27: 1 | D27: 1 | E27: 180 | F27: 2 | G27: Fire Sprinkler Drop Standard Threaded Steel - Dropping into unbraced lay-in tile SOFT ceiling - 6 ft. long drop maximum, SDC A or B
A28: C.20.11.001b | B28: ea | C28: all | D28: 1 | E28: 3 | F28: 3 | G28: Prefabricated steel stair with steel treads and landings with no seismic joint.
A29: D.50.12.021a | B29: ea | C29: all | D29: 1 | E29: 1 | F29: 1 | G29: Low Voltage Switchgear - Capacity: 100 to <350 Amp - Unanchored equipment that is not vibration isolated - Equipment fragility only
A30: D.10.14.011 | B30: ea | C30: all | D30: 1 | E30: 14 | F30: 14 | G30: Traction Elevator – Applies to most California Installations 1976 or later, most western states installations 1982 or later and most other U.S installations 1998 or later.
A31: D.30.31.011a | B31: ea | C31: all | D31: 1 | E31: 16 | F31: 16 | G31: Chiller - Capacity: < 100 Ton - Unanchored equipment that is not vibration isolated - Equipment fragility only
A32: D.30.31.021a | B32: ea | C32: all | D32: 1 | E32: 16 | F32: 16 | G32: Cooling Tower - Capacity: < 100 Ton - Unanchored equipment that is not vibration isolated - Equipment fragility only
A33: D.30.52.011a | B33: ea | C33: all | D33: 1 | E33: 71 | F33: 71 | G33: Air Handling Unit - Capacity: <5000 CFM - Unanchored equipment that is not vibration isolated - Equipment fragility only
A34: D.50.12.013a | B34: ea | C34: all | D34: 1 | E34: 17 | F34: 17 | G34: Motor Control Center - Capacity: all - Unanchored equipment that is not vibration isolated - Equipment fragility only
A35: excessiveRID | B35: ea | C35: all | D35: 1 | E35: 1 | G35: Excessive residual drift
A36: collapse | B36: ea | C36: 19 | D36: 1 | E36: 1 | G36: Collapsed building
A37: irreparable | B37: ea | C37: 19 | D37: 1 | E37: 1 | G37: Irreparable building
A41: Modification log
A42: E.20.22.112a | B42: Removed (Peak floor velocity dependent (non recorded parameter)
A43: E20.22.102a | B43: Removed (Peak floor velocity dependent (non recorded parameter)
...

Sheet Filtered
B2: NOTE :
B3: All directions set to 1, as the frame is only modeled in 1 direction. Could also be set as "0" to represent both directions
C5: Units | D5: Location | E5: Direction | F5: Theta_0 | G5: Blocks | H5: Comment
B6: ='Raw quantities'!Q4 -> B2022.001 | C6: ft2 | D6: 2--19 | E6: 1 | F6: ='Raw quantities'!V4*0.5 -> 3375 | G6: ='Raw quantities'!V34 -> 225 | H6: ='Raw quantities'!T4 -> Curtain Walls - Generic Midrise Stick-Built Curtain wall, Config: Monolithic, Lamination: Unknown, Glass Type: Unknown, Details: Aspect ratio = 6:5, Other details Unknown
B7: ='Raw quantities'!Q4 -> B2022.001 | C7: ft2 | D7: 1 | E7: 1 | F7: ='Raw quantities'!AN4*0.5 -> 675 | G7: ='Raw quantities'!AN34 -> 45 | H7: ='Raw quantities'!T4 -> Curtain Walls - Generic Midrise Stick-Built Curtain wall, Config: Monolithic, Lamination: Unknown, Glass Type: Unknown, Details: Aspect ratio = 6:5, Other details Unknown
B8: ='Raw quantities'!Q5 -> B3011.011 | C8: ft2 | D8: 2--19 | E8: 1 | F8: ='Raw quantities'!V5 -> 6075 | G8: =_xlfn.CEILING.MATH('Raw quantities'!V35) -> 61 | H8: ='Raw quantities'!T5 -> Concrete tile roof, tiles secured and compliant with UBC94
B9: ='Raw quantities'!Q5 -> B3011.011 | C9: ft2 | D9: 1 | E9: 1 | F9: ='Raw quantities'!AN5 -> 11250 | G9: =_xlfn.CEILING.MATH('Raw quantities'!AN35) -> 113 | H9: ='Raw quantities'!T5 -> Concrete tile roof, tiles secured and compliant with UBC94
B10: ='Raw quantities'!Q6 -> C1011.001a | C10: ft | D10: 2--19 | E10: 1 | F10: ='Raw quantities'!V6*0.5 -> 1125 | G10: =_xlfn.CEILING.MATH('Raw quantities'!V36) -> 23 | H10: ='Raw quantities'!T6 -> Wall Partition, Type: Gypsum with metal studs, Full Height, Fixed Below, Fixed Above
B11: ='Raw quantities'!Q6 -> C1011.001a | C11: ft | D11: 1 | E11: 1 | F11: ='Raw quantities'!AN6*0.5 -> 112.5 | G11: =_xlfn.CEILING.MATH('Raw quantities'!AN36) -> 3 | H11: ='Raw quantities'!T6 -> Wall Partition, Type: Gypsum with metal studs, Full Height, Fixed Below, Fixed Above
B12: ='Raw quantities'!Q7 -> C3011.001a | C12: ft | D12: 2--19 | E12: 1 | F12: ='Raw quantities'!V7 -> 170.1 | G12: =_xlfn.CEILING.MATH('Raw quantities'!V37) -> 2 | H12: ='Raw quantities'!T7 -> Wall Partition, Type: Gypsum + Wallpaper, Full Height, Fixed Below, Fixed Above
B13: ='Raw quantities'!Q7 -> C3011.001a | C13: ft | D13: 1 | E13: 1 | F13: ='Raw quantities'!AN7 -> 243 | G13: =_xlfn.CEILING.MATH('Raw quantities'!AN37) -> 3 | H13: ='Raw quantities'!T7 -> Wall Partition, Type: Gypsum + Wallpaper, Full Height, Fixed Below, Fixed Above
B14: ='Raw quantities'!Q8 -> C3027.001 | C14: ft2 | D14: 2--19 | E14: 1 | F14: ='Raw quantities'!V8 -> 16875 | G14: =_xlfn.CEILING.MATH('Raw quantities'!V38) -> 169 | H14: ='Raw quantities'!T8 -> Raised Access Floor, non seismically rated.
B15: ='Raw quantities'!Q9 -> C3032.001a | C15: ft2 | D15: all | E15: 1 | F15: ='Raw quantities'!V9 -> 20250 | G15: ='Raw quantities'!V39 -> 81 | H15: ='Raw quantities'!T9 -> Suspended Ceiling, SDC A,B,C, Area (A): A < 250, Vert support only
B16: ='Raw quantities'!Q10 -> E2022.112a | C16: ea | D16: 2--19 | E16: 1 | F16: ='Raw quantities'!V10 -> 18 | G16: ='Raw quantities'!V40 -> 18 | H16: ='Raw quantities'!T10 -> Vertical Filing Cabinet, 2 drawer, unanchored laterally
B17: ='Raw quantities'!Q11 -> E2022.102a | C17: ea | D17: 2--19 | E17: 1 | F17: ='Raw quantities'!V11 -> 45 | G17: ='Raw quantities'!V41 -> 45 | H17: ='Raw quantities'!T11 -> Bookcase, 2 shelves, unanchored laterally
B18: ='Raw quantities'!Q12 -> D2021.011a | C18: ft | D18: 2--19 | E18: 1 | F18: ='Raw quantities'!V12 -> 945 | G18: =_xlfn.CEILING.MATH('Raw quantities'!V42) -> 1 | H18: ='Raw quantities'!T12 -> Cold or Hot Potable - Small Diameter Threaded Steel - (2.5 inches in diameter or less), SDC A or B, PIPING FRAGILITY
B19: ='Raw quantities'!Q12 -> D2021.011a | C19: ft | D19: 1 | E19: 1 | F19: ='Raw quantities'!AN12 -> 675 | G19: =_xlfn.CEILING.MATH('Raw quantities'!AN42) -> 1 | H19: ='Raw quantities'!T12 -> Cold or Hot Potable - Small Diameter Threaded Steel - (2.5 inches in diameter or less), SDC A or B, PIPING FRAGILITY
B20: ='Raw quantities'!Q13 -> D3041.012a | C20: ft | D20: 2--19 | E20: 1 | F20: ='Raw quantities'!V13 -> 450 | G20: =_xlfn.CEILING.MATH('Raw quantities'!V43) -> 1 | H20: ='Raw quantities'!T13 -> HVAC Galvanized Sheet Metal Ducting - 6 sq. ft cross sectional area or greater, SDC A or B
B21: ='Raw quantities'!Q13 -> D3041.012a | C21: ft | D21: 1 | E21: 1 | F21: ='Raw quantities'!AN13 -> 1125 | G21: =_xlfn.CEILING.MATH('Raw quantities'!AN43) -> 2 | H21: ='Raw quantities'!T13 -> HVAC Galvanized Sheet Metal Ducting - 6 sq. ft cross sectional area or greater, SDC A or B
B22: ='Raw quantities'!Q14 -> D3041.011a | C22: ft | D22: 2--19 | E22: 1 | F22: ='Raw quantities'!V14 -> 1687.5 | G22: =_xlfn.CEILING.MATH('Raw quantities'!V44) -> 2 | H22: ='Raw quantities'!T14 -> HVAC Galvanized Sheet Metal Ducting less than 6 sq. ft in cross sectional area, SDC A or B
B23: ='Raw quantities'!Q14 -> D3041.011a | C23: ft | D23: 1 | E23: 1 | F23: ='Raw quantities'!AN14 -> 112.5 | G23: =_xlfn.CEILING.MATH('Raw quantities'!AN44) -> 1 | H23: ='Raw quantities'!T14 -> HVAC Galvanized Sheet Metal Ducting less than 6 sq. ft in cross sectional area, SDC A or B
B24: ='Raw quantities'!Q15 -> D3041.031a | C24: ea | D24: 2--19 | E24: 1 | F24: =_xlfn.CEILING.MATH('Raw quantities'!V15) -> 203 | G24: =_xlfn.CEILING.MATH('Raw quantities'!V45) -> 21 | H24: ='Raw quantities'!T15 -> HVAC Drops / Diffusers in suspended ceilings - No independent safety wires, SDC A or B
B25: ='Raw quantities'!Q16 -> D3041.041a | C25: ea | D25: 2--19 | E25: 1 | F25: =_xlfn.CEILING.MATH('Raw quantities'!V16) -> 113 | G25: =_xlfn.CEILING.MATH('Raw quantities'!V46) -> 12 | H25: ='Raw quantities'!T16 -> Variable Air Volume (VAV) box with in-line coil, SDC A or B
B26: ='Raw quantities'!Q16 -> D3041.041a | C26: ea | D26: 1 | E26: 1 | F26: ='Raw quantities'!AN16 -> 90 | G26: ='Raw quantities'!AN46 -> 9 | H26: ='Raw quantities'!T16 -> Variable Air Volume (VAV) box with in-line coil, SDC A or B
B27: ='Raw quantities'!Q17 -> C3034.001 | C27: ea | D27: all | E27: 1 | F27: =_xlfn.CEILING.MATH('Raw quantities'!V17) -> 338 | G27: =_xlfn.CEILING.MATH('Raw quantities'!V47) -> 338 | H27: ='Raw quantities'!T17 -> Independent Pendant Lighting - non seismic
B28: ='Raw quantities'!Q18 -> D4011.021a | C28: ft | D28: 2--19 | E28: 1 | F28: ='Raw quantities'!V18 -> 4500 | G28: =_xlfn.CEILING.MATH('Raw quantities'!V48) -> 5 | H28: ='Raw quantities'!T18 -> Fire Sprinkler Water Piping - Horizontal Mains and Branches - Old Style Victaulic - Thin Wall Steel - No bracing, SDC A or B, PIPING FRAGILITY
B29: ='Raw quantities'!Q18 -> D4011.021a | C29: ft | D29: 1 | E29: 1 | F29: ='Raw quantities'!AN18 -> 4050 | G29: =_xlfn.CEILING.MATH('Raw quantities'!AN48) -> 5 | H29: ='Raw quantities'!T18 -> Fire Sprinkler Water Piping - Horizontal Mains and Branches - Old Style Victaulic - Thin Wall Steel - No bracing, SDC A or B, PIPING FRAGILITY
B30: ='Raw quantities'!Q19 -> D4011.031a | C30: ea | D30: 2--19 | E30: 1 | F30: =_xlfn.CEILING.MATH('Raw quantities'!V19) -> 203 | G30: =_xlfn.CEILING.MATH('Raw quantities'!V49) -> 3 | H30: ='Raw quantities'!T19 -> Fire Sprinkler Drop Standard Threaded Steel - Dropping into unbraced lay-in tile SOFT ceiling - 6 ft. long drop maximum, SDC A or B
B31: ='Raw quantities'!Q19 -> D4011.031a | C31: ea | D31: 1 | E31: 1 | F31: ='Raw quantities'!AN19 -> 180 | G31: =_xlfn.CEILING.MATH('Raw quantities'!AN49) -> 2 | H31: ='Raw quantities'!T19 -> Fire Sprinkler Drop Standard Threaded Steel - Dropping into unbraced lay-in tile SOFT ceiling - 6 ft. long drop maximum, SDC A or B
B32: C2011.001b | C32: ea | D32: all | E32: 1 | F32: =_xlfn.CEILING.MATH('Raw quantities'!V21*0.5) -> 3 | G32: =_xlfn.CEILING.MATH('Raw quantities'!V51) -> 3 | H32: ='Raw quantities'!T21 -> Prefabricated steel stair with steel treads and landings with seismic joints that accommodate drift.
A33: AP = AMP (225 AMP unit) | B33: ='Raw quantities'!Q22 -> D5012.021a | C33: ='Raw quantities'!U22 -> AP | D33: all | E33: 1 | F33: =_xlfn.CEILING.MATH('Raw quantities'!V22*0.5/225) -> 1 | G33: =_xlfn.CEILING.MATH('Raw quantities'!V52) -> 1 | H33: ='Raw quantities'!T22 -> Low Voltage Switchgear - Capacity: 100 to <350 Amp - Unanchored equipment that is not vibration isolated - Equipment fragility only
B34: ='Raw quantities'!Q23 -> D1014.011 | C34: ea | D34: all | E34: 1 | F34: =_xlfn.CEILING.MATH('Raw quantities'!AO23) -> 14 | G34: =_xlfn.CEILING.MATH('Raw quantities'!AO53) -> 14 | H34: ='Raw quantities'!T23 -> Traction Elevator – Applies to most California Installations 1976 or later, most western states installations 1982 or later and most other U.S installations 1998 or later.
A35: TN = TON (75 TON unit) | B35: ='Raw quantities'!Q24 -> D3031.011a | C35: ='Raw quantities'!U24 -> TN | D35: all | E35: 1 | F35: =_xlfn.CEILING.MATH('Raw quantities'!AO24/75) -> 16 | G35: =_xlfn.CEILING.MATH('Raw quantities'!AO54) -> 16 | H35: ='Raw quantities'!T24 -> Chiller - Capacity: < 100 Ton - Unanchored equipment that is not vibration isolated - Equipment fragility only
A36: TN = TON (75 TON unit) | B36: ='Raw quantities'!Q25 -> D3031.021a | C36: ='Raw quantities'!U25 -> TN | D36: all | E36: 1 | F36: =_xlfn.CEILING.MATH('Raw quantities'!AO25/75) -> 16 | G36: =_xlfn.CEILING.MATH('Raw quantities'!AO55) -> 16 | H36: ='Raw quantities'!T25 -> Cooling Tower - Capacity: < 100 Ton - Unanchored equipment that is not vibration isolated - Equipment fragility only
A37: TN = TON (75 TON unit) | B37: ='Raw quantities'!Q26 -> D3052.011a | C37: ='Raw quantities'!U26 -> CF | D37: all | E37: 1 | F37: =_xlfn.CEILING.MATH('Raw quantities'!AO26/4000) -> 71 | G37: =_xlfn.CEILING.MATH('Raw quantities'!AO56) -> 71 | H37: ='Raw quantities'!T26 -> Air Handling Unit - Capacity: <5000 CFM - Unanchored equipment that is not vibration isolated - Equipment fragility only
B38: ='Raw quantities'!Q27 -> D5012.013a | C38: ea | D38: all | E38: 1 | F38: =_xlfn.CEILING.MATH('Raw quantities'!AO27) -> 17 | G38: =_xlfn.CEILING.MATH('Raw quantities'!AO57) -> 17 | H38: ='Raw quantities'!T27 -> Motor Control Center - Capacity: all - Unanchored equipment that is not vibration isolated - Equipment fragility only
B40: excessiveRID | C40: ea | D40: all | E40: 1 | F40: 1 | H40: Excessive residual drift
B41: collapse | C41: ea | D41: 0 | E41: 1 | F41: 1 | H41: Collapsed building
B42: irreparable | C42: ea | D42: 0 | E42: 1 | F42: 1 | H42: Irreparable building
B45: Structural components (manually added)
...

Sheet Raw quantities
C2: NORMATIVE QTY ESTIMATION TOOL | Q2: UNIQUES | V2: Floor quantities
B3: FLOOR ID | C3: ID | D3: Name | E3: QTY/component | F3: Nb of directional components | G3: Nb of non directional component | H3: Correlation | I3: Total quantity | J3: Unit | L3: Blocks | Q3: ID | R3: Names | S3: Pasted Names | T3: Text Names | U3: Units | V3: 18th | W3: 17th | X3: 16th | Y3: 15th | Z3: 14th | AA3: 13th | AB3: 12th | AC3: 11th | AD3: 10th | AE3: 9th | AF3: 8th | AG3: 7th | AH3: 6th | AI3: 5th | AJ3: 4th | AK3: 3rd | AL3: 2nd | AM3: 1st | AN3: Ground | AO3: ALL
B4: 18th | C4: B2022.001 | D4: B2022.001 Curtain Walls - Generic Midrise Stick-Built Curtain wall, Config: Monolithic, Lamination: Unknown, Glass Type: Unknown, Details: Aspect ratio = 6:5, Other details Unknown | E4: 30 SF | F4: 225 | G4: -- | H4: NO | I4: 6750 | J4: SF | L4: =MAX(F4:G4) -> 225 | Q4: {=_xlfn.UNIQUE(C4:C444)} -> B2022.001 | R4: {=VLOOKUP(_xlfn.ANCHORARRAY(Q4),C4:D444,2,FALSE)} -> B2022.001 Curtain Walls - Generic Midrise Stick-Built Curtain wall, Config: Monolithic, Lamination: Unknown, Glass Type: Unknown, Details: Aspect ratio = 6:5, Other details Unknown | S4: B2022.001 Curtain Walls - Generic Midrise Stick-Built Curtain wall, Config: Monolithic, Lamination: Unknown, Glass Type: Unknown, Details: Aspect ratio = 6:5, Other details Unknown | T4: =RIGHT(S4,LEN(S4)-FIND(" ",S4)) -> Curtain Walls - Generic Midrise Stick-Built Curtain wall, Config: Monolithic, Lamination: Unknown, Glass Type: Unknown, Details: Aspect ratio = 6:5, Other details Unknown | U4: {=VLOOKUP(_xlfn.ANCHORARRAY(Q4),C4:J444,8,FALSE)} -> SF | V4: {=INDEX($I$4:$I$444,MATCH(1,($C$4:$C$444=$Q4)*($B$4:$B$444=V$3),0))} -> 6750 | W4: {=INDEX($I$4:$I$444,MATCH(1,($C$4:$C$444=$Q4)*($B$4:$B$444=W$3),0))} -> 6750 | X4: {=INDEX($I$4:$I$444,MATCH(1,($C$4:$C$444=$Q4)*($B$4:$B$444=X$3),0))} -> 6750 | Y4: {=INDEX($I$4:$I$444,MATCH(1,($C$4:$C$444=$Q4)*($B$4:$B$444=Y$3),0))} -> 6750 | Z4: {=INDEX($I$4:$I$444,MATCH(1,($C$4:$C$444=$Q4)*($B$4:$B$444=Z$3),0))} -> 6750 | AA4: {=INDEX($I$4:$I$444,MATCH(1,($C$4:$C$444=$Q4)*($B$4:$B$444=AA$3),0))} -> 6750 | AB4: {=INDEX($I$4:$I$444,MATCH(1,($C$4:$C$444=$Q4)*($B$4:$B$444=AB$3),0))} -> 6750 | AC4: {=INDEX($I$4:$I$444,MATCH(1,($C$4:$C$444=$Q4)*($B$4:$B$444=AC$3),0))} -> 6750 | ... AN4: {=INDEX($I$4:$I$444,MATCH(1,($C$4:$C$444=$Q4)*($B$4:$B$444=AN$3),0))} -> 1350 | AO4: -
B5: 18th | C5: B3011.011 | D5: B3011.011 Concrete tile roof, tiles secured and compliant with UBC94 | E5: 100 SF | F5: -- | G5: 60.75 | H5: NO | I5: 6075 | J5: SF | L5: =MAX(F5:G5) -> 60.75 | Q5: B3011.011 | R5: B3011.011 Concrete tile roof, tiles secured and compliant with UBC94 | S5: B3011.011 Concrete tile roof, tiles secured and compliant with UBC94 | T5: =RIGHT(S5,LEN(S5)-FIND(" ",S5)) -> Concrete tile roof, tiles secured and compliant with UBC94 | U5: SF | V5: {=INDEX($I$4:$I$444,MATCH(1,($C$4:$C$444=$Q5)*($B$4:$B$444=V$3),0))} -> 6075 | W5: {=INDEX($I$4:$I$444,MATCH(1,($C$4:$C$444=$Q5)*($B$4:$B$444=W$3),0))} -> 6075 | X5: {=INDEX($I$4:$I$444,MATCH(1,($C$4:$C$444=$Q5)*($B$4:$B$444=X$3),0))} -> 6075 | Y5: {=INDEX($I$4:$I$444,MATCH(1,($C$4:$C$444=$Q5)*($B$4:$B$444=Y$3),0))} -> 6075 | Z5: {=INDEX($I$4:$I$444,MATCH(1,($C$4:$C$444=$Q5)*($B$4:$B$444=Z$3),0))} -> 6075 | AA5: {=INDEX($I$4:$I$444,MATCH(1,($C$4:$C$444=$Q5)*($B$4:$B$444=AA$3),0))} -> 6075 | AB5: {=INDEX($I$4:$I$444,MATCH(1,($C$4:$C$444=$Q5)*($B$4:$B$444=AB$3),0))} -> 6075 | AC5: {=INDEX($I$4:$I$444,MATCH(1,($C$4:$C$444=$Q5)*($B$4:$B$444=AC$3),0))} -> 6075 | ... AN5: {=INDEX($I$4:$I$444,MATCH(1,($C$4:$C$444=$Q5)*($B$4:$B$444=AN$3),0))} -> 11250 | AO5: -
B6: 18th | C6: C1011.001a | D6: C1011.001a Wall Partition, Type: Gypsum with metal studs, Full Height, Fixed Below, Fixed Above | E6: 100 LF | F6: 22.5 | G6: -- | H6: NO | I6: 2250 | J6: LF | L6: =MAX(F6:G6) -> 22.5 | Q6: C1011.001a | R6: C1011.001a Wall Partition, Type: Gypsum with metal studs, Full Height, Fixed Below, Fixed Above | S6: C1011.001a Wall Partition, Type: Gypsum with metal studs, Full Height, Fixed Below, Fixed Above | T6: =RIGHT(S6,LEN(S6)-FIND(" ",S6)) -> Wall Partition, Type: Gypsum with metal studs, Full Height, Fixed Below, Fixed Above | U6: LF | V6: {=INDEX($I$4:$I$444,MATCH(1,($C$4:$C$444=$Q6)*($B$4:$B$444=V$3),0))} -> 2250 | W6: {=INDEX($I$4:$I$444,MATCH(1,($C$4:$C$444=$Q6)*($B$4:$B$444=W$3),0))} -> 2250 | X6: {=INDEX($I$4:$I$444,MATCH(1,($C$4:$C$444=$Q6)*($B$4:$B$444=X$3),0))} -> 2250 | Y6: {=INDEX($I$4:$I$444,MATCH(1,($C$4:$C$444=$Q6)*($B$4:$B$444=Y$3),0))} -> 2250 | Z6: {=INDEX($I$4:$I$444,MATCH(1,($C$4:$C$444=$Q6)*($B$4:$B$444=Z$3),0))} -> 2250 | AA6: {=INDEX($I$4:$I$444,MATCH(1,($C$4:$C$444=$Q6)*($B$4:$B$444=AA$3),0))} -> 2250 | AB6: {=INDEX($I$4:$I$444,MATCH(1,($C$4:$C$444=$Q6)*($B$4:$B$444=AB$3),0))} -> 2250 | AC6: {=INDEX($I$4:$I$444,MATCH(1,($C$4:$C$444=$Q6)*($B$4:$B$444=AC$3),0))} -> 2250 | ... AN6: {=INDEX($I$4:$I$444,MATCH(1,($C$4:$C$444=$Q6)*($B$4:$B$444=AN$3),0))} -> 225 | AO6: -
B7: 18th | C7: C3011.001a | D7: C3011.001a Wall Partition, Type: Gypsum + Wallpaper, Full Height, Fixed Below, Fixed Above | E7: 100 LF | F7: 1.701 | G7: -- | H7: NO | I7: 170.1 | J7: LF | L7: =MAX(F7:G7) -> 1.701 | Q7: C3011.001a | R7: C3011.001a Wall Partition, Type: Gypsum + Wallpaper, Full Height, Fixed Below, Fixed Above | S7: C3011.001a Wall Partition, Type: Gypsum + Wallpaper, Full Height, Fixed Below, Fixed Above | T7: =RIGHT(S7,LEN(S7)-FIND(" ",S7)) -> Wall Partition, Type: Gypsum + Wallpaper, Full Height, Fixed Below, Fixed Above | U7: LF | V7: {=INDEX($I$4:$I$444,MATCH(1,($C$4:$C$444=$Q7)*($B$4:$B$444=V$3),0))} -> 170.1 | W7: {=INDEX($I$4:$I$444,MATCH(1,($C$4:$C$444=$Q7)*($B$4:$B$444=W$3),0))} -> 170.1 | X7: {=INDEX($I$4:$I$444,MATCH(1,($C$4:$C$444=$Q7)*($B$4:$B$444=X$3),0))} -> 170.1 | Y7: {=INDEX($I$4:$I$444,MATCH(1,($C$4:$C$444=$Q7)*($B$4:$B$444=Y$3),0))} -> 170.1 | Z7: {=INDEX($I$4:$I$444,MATCH(1,($C$4:$C$444=$Q7)*($B$4:$B$444=Z$3),0))} -> 170.1 | AA7: {=INDEX($I$4:$I$444,MATCH(1,($C$4:$C$444=$Q7)*($B$4:$B$444=AA$3),0))} -> 170.1 | AB7: {=INDEX($I$4:$I$444,MATCH(1,($C$4:$C$444=$Q7)*($B$4:$B$444=AB$3),0))} -> 170.1 | AC7: {=INDEX($I$4:$I$444,MATCH(1,($C$4:$C$444=$Q7)*($B$4:$B$444=AC$3),0))} -> 170.1 | ... AN7: {=INDEX($I$4:$I$444,MATCH(1,($C$4:$C$444=$Q7)*($B$4:$B$444=AN$3),0))} -> 243 | AO7: -
B8: 18th | C8: C3027.001 | D8: C3027.001 Raised Access Floor, non seismically rated. | E8: 100 SF | F8: -- | G8: 168.75 | H8: NO | I8: 16875 | J8: SF | L8: =MAX(F8:G8) -> 168.75 | Q8: C3027.001 | R8: C3027.001 Raised Access Floor, non seismically rated. | S8: C3027.001 Raised Access Floor, non seismically rated. | T8: =RIGHT(S8,LEN(S8)-FIND(" ",S8)) -> Raised Access Floor, non seismically rated. | U8: SF | V8: {=INDEX($I$4:$I$444,MATCH(1,($C$4:$C$444=$Q8)*($B$4:$B$444=V$3),0))} -> 16875 | W8: {=INDEX($I$4:$I$444,MATCH(1,($C$4:$C$444=$Q8)*($B$4:$B$444=W$3),0))} -> 16875 | X8: {=INDEX($I$4:$I$444,MATCH(1,($C$4:$C$444=$Q8)*($B$4:$B$444=X$3),0))} -> 16875 | Y8: {=INDEX($I$4:$I$444,MATCH(1,($C$4:$C$444=$Q8)*($B$4:$B$444=Y$3),0))} -> 16875 | Z8: {=INDEX($I$4:$I$444,MATCH(1,($C$4:$C$444=$Q8)*($B$4:$B$444=Z$3),0))} -> 16875 | AA8: {=INDEX($I$4:$I$444,MATCH(1,($C$4:$C$444=$Q8)*($B$4:$B$444=AA$3),0))} -> 16875 | AB8: {=INDEX($I$4:$I$444,MATCH(1,($C$4:$C$444=$Q8)*($B$4:$B$444=AB$3),0))} -> 16875 | AC8: {=INDEX($I$4:$I$444,MATCH(1,($C$4:$C$444=$Q8)*($B$4:$B$444=AC$3),0))} -> 16875 | ... AM8: {=INDEX($I$4:$I$444,MATCH(1,($C$4:$C$444=$Q8)*($B$4:$B$444=AM$3),0))} -> 16875 | AN8: - | AO8: -
B9: 18th | C9: C3032.001a | D9: C3032.001a Suspended Ceiling, SDC A,B,C, Area (A): A < 250, Vert support only | E9: 250 SF | F9: -- | G9: 81 | H9: NO | I9: 20250 | J9: SF | L9: =MAX(F9:G9) -> 81 | Q9: C3032.001a | R9: C3032.001a Suspended Ceiling, SDC A,B,C, Area (A): A < 250, Vert support only | S9: C3032.001a Suspended Ceiling, SDC A,B,C, Area (A): A < 250, Vert support only | T9: =RIGHT(S9,LEN(S9)-FIND(" ",S9)) -> Suspended Ceiling, SDC A,B,C, Area (A): A < 250, Vert support only | U9: SF | V9: {=INDEX($I$4:$I$444,MATCH(1,($C$4:$C$444=$Q9)*($B$4:$B$444=V$3),0))} -> 20250 | W9: {=INDEX($I$4:$I$444,MATCH(1,($C$4:$C$444=$Q9)*($B$4:$B$444=W$3),0))} -> 20250 | X9: {=INDEX($I$4:$I$444,MATCH(1,($C$4:$C$444=$Q9)*($B$4:$B$444=X$3),0))} -> 20250 | Y9: {=INDEX($I$4:$I$444,MATCH(1,($C$4:$C$444=$Q9)*($B$4:$B$444=Y$3),0))} -> 20250 | Z9: {=INDEX($I$4:$I$444,MATCH(1,($C$4:$C$444=$Q9)*($B$4:$B$444=Z$3),0))} -> 20250 | AA9: {=INDEX($I$4:$I$444,MATCH(1,($C$4:$C$444=$Q9)*($B$4:$B$444=AA$3),0))} -> 20250 | AB9: {=INDEX($I$4:$I$444,MATCH(1,($C$4:$C$444=$Q9)*($B$4:$B$444=AB$3),0))} -> 20250 | AC9: {=INDEX($I$4:$I$444,MATCH(1,($C$4:$C$444=$Q9)*($B$4:$B$444=AC$3),0))} -> 20250 | ... AN9: {=INDEX($I$4:$I$444,MATCH(1,($C$4:$C$444=$Q9)*($B$4:$B$444=AN$3),0))} -> 20250 | AO9: -
B10: 18th | C10: C3032.001a | D10: C3032.001a Suspended Ceiling, SDC A,B,C, Area (A): A < 250, Vert support only | E10: 250 SF | F10: -- | G10: 4.5 | H10: NO | I10: 1125 | J10: SF | L10: =MAX(F10:G10) -> 4.5 | Q10: E2022.112a | R10: E2022.112a Vertical Filing Cabinet, 2 drawer, unanchored laterally | S10: E2022.112a Vertical Filing Cabinet, 2 drawer, unanchored laterally | T10: =RIGHT(S10,LEN(S10)-FIND(" ",S10)) -> Vertical Filing Cabinet, 2 drawer, unanchored laterally | U10: EA | V10: {=INDEX($I$4:$I$444,MATCH(1,($C$4:$C$444=$Q10)*($B$4:$B$444=V$3),0))} -> 18 | W10: {=INDEX($I$4:$I$444,MATCH(1,($C$4:$C$444=$Q10)*($B$4:$B$444=W$3),0))} -> 18 | X10: {=INDEX($I$4:$I$444,MATCH(1,($C$4:$C$444=$Q10)*($B$4:$B$444=X$3),0))} -> 18 | Y10: {=INDEX($I$4:$I$444,MATCH(1,($C$4:$C$444=$Q10)*($B$4:$B$444=Y$3),0))} -> 18 | Z10: {=INDEX($I$4:$I$444,MATCH(1,($C$4:$C$444=$Q10)*($B$4:$B$444=Z$3),0))} -> 18 | AA10: {=INDEX($I$4:$I$444,MATCH(1,($C$4:$C$444=$Q10)*($B$4:$B$444=AA$3),0))} -> 18 | AB10: {=INDEX($I$4:$I$444,MATCH(1,($C$4:$C$444=$Q10)*($B$4:$B$444=AB$3),0))} -> 18 | AC10: {=INDEX($I$4:$I$444,MATCH(1,($C$4:$C$444=$Q10)*($B$4:$B$444=AC$3),0))} -> 18 | ... AM10: {=INDEX($I$4:$I$444,MATCH(1,($C$4:$C$444=$Q10)*($B$4:$B$444=AM$3),0))} -> 18 | AN10: - | AO10: -
B11: 18th | C11: C3032.001a | D11: C3032.001a Suspended Ceiling, SDC A,B,C, Area (A): A < 250, Vert support only | E11: 250 SF | F11: -- | G11: 2.7 | H11: NO | I11: 675 | J11: SF | L11: =MAX(F11:G11) -> 2.7 | Q11: E2022.102a | R11: E2022.102a Bookcase, 2 shelves, unanchored laterally | S11: E2022.102a Bookcase, 2 shelves, unanchored laterally | T11: =RIGHT(S11,LEN(S11)-FIND(" ",S11)) -> Bookcase, 2 shelves, unanchored laterally | U11: EA | V11: {=INDEX($I$4:$I$444,MATCH(1,($C$4:$C$444=$Q11)*($B$4:$B$444=V$3),0))} -> 45 | W11: {=INDEX($I$4:$I$444,MATCH(1,($C$4:$C$444=$Q11)*($B$4:$B$444=W$3),0))} -> 45 | X11: {=INDEX($I$4:$I$444,MATCH(1,($C$4:$C$444=$Q11)*($B$4:$B$444=X$3),0))} -> 45 | Y11: {=INDEX($I$4:$I$444,MATCH(1,($C$4:$C$444=$Q11)*($B$4:$B$444=Y$3),0))} -> 45 | Z11: {=INDEX($I$4:$I$444,MATCH(1,($C$4:$C$444=$Q11)*($B$4:$B$444=Z$3),0))} -> 45 | AA11: {=INDEX($I$4:$I$444,MATCH(1,($C$4:$C$444=$Q11)*($B$4:$B$444=AA$3),0))} -> 45 | AB11: {=INDEX($I$4:$I$444,MATCH(1,($C$4:$C$444=$Q11)*($B$4:$B$444=AB$3),0))} -> 45 | AC11: {=INDEX($I$4:$I$444,MATCH(1,($C$4:$C$444=$Q11)*($B$4:$B$444=AC$3),0))} -> 45 | ... AM11: {=INDEX($I$4:$I$444,MATCH(1,($C$4:$C$444=$Q11)*($B$4:$B$444=AM$3),0))} -> 45 | AN11: - | AO11: -
B12: 18th | C12: C3032.001a | D12: C3032.001a Suspended Ceiling, SDC A,B,C, Area (A): A < 250, Vert support only | E12: 250 SF | F12: -- | G12: 1.8 | H12: NO | I12: 450 | J12: SF | L12: =MAX(F12:G12) -> 1.8 | Q12: D2021.011a | R12: D2021.011a Cold or Hot Potable - Small Diameter Threaded Steel - (2.5 inches in diameter or less), SDC A or B, PIPING FRAGILITY | S12: D2021.011a Cold or Hot Potable - Small Diameter Threaded Steel - (2.5 inches in diameter or less), SDC A or B, PIPING FRAGILITY | T12: =RIGHT(S12,LEN(S12)-FIND(" ",S12)) -> Cold or Hot Potable - Small Diameter Threaded Steel - (2.5 inches in diameter or less), SDC A or B, PIPING FRAGILITY | U12: LF | V12: {=INDEX($I$4:$I$444,MATCH(1,($C$4:$C$444=$Q12)*($B$4:$B$444=V$3),0))} -> 945 | W12: {=INDEX($I$4:$I$444,MATCH(1,($C$4:$C$444=$Q12)*($B$4:$B$444=W$3),0))} -> 945 | X12: {=INDEX($I$4:$I$444,MATCH(1,($C$4:$C$444=$Q12)*($B$4:$B$444=X$3),0))} -> 945 | Y12: {=INDEX($I$4:$I$444,MATCH(1,($C$4:$C$444=$Q12)*($B$4:$B$444=Y$3),0))} -> 945 | Z12: {=INDEX($I$4:$I$444,MATCH(1,($C$4:$C$444=$Q12)*($B$4:$B$444=Z$3),0))} -> 945 | AA12: {=INDEX($I$4:$I$444,MATCH(1,($C$4:$C$444=$Q12)*($B$4:$B$444=AA$3),0))} -> 945 | AB12: {=INDEX($I$4:$I$444,MATCH(1,($C$4:$C$444=$Q12)*($B$4:$B$444=AB$3),0))} -> 945 | AC12: {=INDEX($I$4:$I$444,MATCH(1,($C$4:$C$444=$Q12)*($B$4:$B$444=AC$3),0))} -> 945 | ... AN12: {=INDEX($I$4:$I$444,MATCH(1,($C$4:$C$444=$Q12)*($B$4:$B$444=AN$3),0))} -> 675 | AO12: -
B13: 18th | C13: E2022.112a | D13: E2022.112a Vertical Filing Cabinet, 2 drawer, unanchored laterally | E13: 1 EA | F13: -- | G13: 18 | H13: NO | I13: 18 | J13: EA | L13: =MAX(F13:G13) -> 18 | Q13: D3041.012a | R13: D3041.012a HVAC Galvanized Sheet Metal Ducting - 6 sq. ft cross sectional area or greater, SDC A or B | S13: D3041.012a HVAC Galvanized Sheet Metal Ducting - 6 sq. ft cross sectional area or greater, SDC A or B | T13: =RIGHT(S13,LEN(S13)-FIND(" ",S13)) -> HVAC Galvanized Sheet Metal Ducting - 6 sq. ft cross sectional area or greater, SDC A or B | U13: LF | V13: {=INDEX($I$4:$I$444,MATCH(1,($C$4:$C$444=$Q13)*($B$4:$B$444=V$3),0))} -> 450 | W13: {=INDEX($I$4:$I$444,MATCH(1,($C$4:$C$444=$Q13)*($B$4:$B$444=W$3),0))} -> 450 | X13: {=INDEX($I$4:$I$444,MATCH(1,($C$4:$C$444=$Q13)*($B$4:$B$444=X$3),0))} -> 450 | Y13: {=INDEX($I$4:$I$444,MATCH(1,($C$4:$C$444=$Q13)*($B$4:$B$444=Y$3),0))} -> 450 | Z13: {=INDEX($I$4:$I$444,MATCH(1,($C$4:$C$444=$Q13)*($B$4:$B$444=Z$3),0))} -> 450 | AA13: {=INDEX($I$4:$I$444,MATCH(1,($C$4:$C$444=$Q13)*($B$4:$B$444=AA$3),0))} -> 450 | AB13: {=INDEX($I$4:$I$444,MATCH(1,($C$4:$C$444=$Q13)*($B$4:$B$444=AB$3),0))} -> 450 | AC13: {=INDEX($I$4:$I$444,MATCH(1,($C$4:$C$444=$Q13)*($B$4:$B$444=AC$3),0))} -> 450 | ... AN13: {=INDEX($I$4:$I$444,MATCH(1,($C$4:$C$444=$Q13)*($B$4:$B$444=AN$3),0))} -> 1125 | AO13: -
B14: 18th | C14: E2022.102a | D14: E2022.102a Bookcase, 2 shelves, unanchored laterally | E14: 1 EA | F14: -- | G14: 45 | H14: NO | I14: 45 | J14: EA | L14: =MAX(F14:G14) -> 45 | Q14: D3041.011a | R14: D3041.011a HVAC Galvanized Sheet Metal Ducting less than 6 sq. ft in cross sectional area, SDC A or B | S14: D3041.011a HVAC Galvanized Sheet Metal Ducting less than 6 sq. ft in cross sectional area, SDC A or B | T14: =RIGHT(S14,LEN(S14)-FIND(" ",S14)) -> HVAC Galvanized Sheet Metal Ducting less than 6 sq. ft in cross sectional area, SDC A or B | U14: LF | V14: {=INDEX($I$4:$I$444,MATCH(1,($C$4:$C$444=$Q14)*($B$4:$B$444=V$3),0))} -> 1687.5 | W14: {=INDEX($I$4:$I$444,MATCH(1,($C$4:$C$444=$Q14)*($B$4:$B$444=W$3),0))} -> 1687.5 | X14: {=INDEX($I$4:$I$444,MATCH(1,($C$4:$C$444=$Q14)*($B$4:$B$444=X$3),0))} -> 1687.5 | Y14: {=INDEX($I$4:$I$444,MATCH(1,($C$4:$C$444=$Q14)*($B$4:$B$444=Y$3),0))} -> 1687.5 | Z14: {=INDEX($I$4:$I$444,MATCH(1,($C$4:$C$444=$Q14)*($B$4:$B$444=Z$3),0))} -> 1687.5 | AA14: {=INDEX($I$4:$I$444,MATCH(1,($C$4:$C$444=$Q14)*($B$4:$B$444=AA$3),0))} -> 1687.5 | AB14: {=INDEX($I$4:$I$444,MATCH(1,($C$4:$C$444=$Q14)*($B$4:$B$444=AB$3),0))} -> 1687.5 | AC14: {=INDEX($I$4:$I$444,MATCH(1,($C$4:$C$444=$Q14)*($B$4:$B$444=AC$3),0))} -> 1687.5 | ... AN14: {=INDEX($I$4:$I$444,MATCH(1,($C$4:$C$444=$Q14)*($B$4:$B$444=AN$3),0))} -> 112.5 | AO14: -
B15: 18th | C15: D2021.011a | D15: D2021.011a Cold or Hot Potable - Small Diameter Threaded Steel - (2.5 inches in diameter or less), SDC A or B, PIPING FRAGILITY | E15: 1000 LF | F15: -- | G15: 0.945 | H15: NO | I15: 945 | J15: LF | L15: =MAX(F15:G15) -> 0.945 | Q15: D3041.031a | R15: D3041.031a HVAC Drops / Diffusers in suspended ceilings - No independent safety wires, SDC A or B | S15: D3041.031a HVAC Drops / Diffusers in suspended ceilings - No independent safety wires, SDC A or B | T15: =RIGHT(S15,LEN(S15)-FIND(" ",S15)) -> HVAC Drops / Diffusers in suspended ceilings - No independent safety wires, SDC A or B | U15: EA | V15: {=INDEX($I$4:$I$444,MATCH(1,($C$4:$C$444=$Q15)*($B$4:$B$444=V$3),0))} -> 202.5 | W15: {=INDEX($I$4:$I$444,MATCH(1,($C$4:$C$444=$Q15)*($B$4:$B$444=W$3),0))} -> 202.5 | X15: {=INDEX($I$4:$I$444,MATCH(1,($C$4:$C$444=$Q15)*($B$4:$B$444=X$3),0))} -> 202.5 | Y15: {=INDEX($I$4:$I$444,MATCH(1,($C$4:$C$444=$Q15)*($B$4:$B$444=Y$3),0))} -> 202.5 | Z15: {=INDEX($I$4:$I$444,MATCH(1,($C$4:$C$444=$Q15)*($B$4:$B$444=Z$3),0))} -> 202.5 | AA15: {=INDEX($I$4:$I$444,MATCH(1,($C$4:$C$444=$Q15)*($B$4:$B$444=AA$3),0))} -> 202.5 | AB15: {=INDEX($I$4:$I$444,MATCH(1,($C$4:$C$444=$Q15)*($B$4:$B$444=AB$3),0))} -> 202.5 | AC15: {=INDEX($I$4:$I$444,MATCH(1,($C$4:$C$444=$Q15)*($B$4:$B$444=AC$3),0))} -> 202.5 | ... AM15: {=INDEX($I$4:$I$444,MATCH(1,($C$4:$C$444=$Q15)*($B$4:$B$444=AM$3),0))} -> 202.5 | AN15: - | AO15: -
B16: 18th | C16: D3041.012a | D16: D3041.012a HVAC Galvanized Sheet Metal Ducting - 6 sq. ft cross sectional area or greater, SDC A or B | E16: 1000 LF | F16: -- | G16: 0.45 | H16: NO | I16: 450 | J16: LF | L16: =MAX(F16:G16) -> 0.45 | Q16: D3041.041a | R16: D3041.041a Variable Air Volume (VAV) box with in-line coil, SDC A or B | S16: D3041.041a Variable Air Volume (VAV) box with in-line coil, SDC A or B | T16: =RIGHT(S16,LEN(S16)-FIND(" ",S16)) -> Variable Air Volume (VAV) box with in-line coil, SDC A or B | U16: EA | V16: {=INDEX($I$4:$I$444,MATCH(1,($C$4:$C$444=$Q16)*($B$4:$B$444=V$3),0))} -> 112.5 | W16: {=INDEX($I$4:$I$444,MATCH(1,($C$4:$C$444=$Q16)*($B$4:$B$444=W$3),0))} -> 112.5 | X16: {=INDEX($I$4:$I$444,MATCH(1,($C$4:$C$444=$Q16)*($B$4:$B$444=X$3),0))} -> 112.5 | Y16: {=INDEX($I$4:$I$444,MATCH(1,($C$4:$C$444=$Q16)*($B$4:$B$444=Y$3),0))} -> 112.5 | Z16: {=INDEX($I$4:$I$444,MATCH(1,($C$4:$C$444=$Q16)*($B$4:$B$444=Z$3),0))} -> 112.5 | AA16: {=INDEX($I$4:$I$444,MATCH(1,($C$4:$C$444=$Q16)*($B$4:$B$444=AA$3),0))} -> 112.5 | AB16: {=INDEX($I$4:$I$444,MATCH(1,($C$4:$C$444=$Q16)*($B$4:$B$444=AB$3),0))} -> 112.5 | AC16: {=INDEX($I$4:$I$444,MATCH(1,($C$4:$C$444=$Q16)*($B$4:$B$444=AC$3),0))} -> 112.5 | ... AN16: {=INDEX($I$4:$I$444,MATCH(1,($C$4:$C$444=$Q16)*($B$4:$B$444=AN$3),0))} -> 90 | AO16: -
B17: 18th | C17: D3041.011a | D17: D3041.011a HVAC Galvanized Sheet Metal Ducting less than 6 sq. ft in cross sectional area, SDC A or B | E17: 1000 LF | F17: -- | G17: 1.6875 | H17: NO | I17: 1687.5 | J17: LF | L17: =MAX(F17:G17) -> 1.6875 | Q17: C3034.001 | R17: C3034.001 Independent Pendant Lighting - non seismic | S17: C3034.001 Independent Pendant Lighting - non seismic | T17: =RIGHT(S17,LEN(S17)-FIND(" ",S17)) -> Independent Pendant Lighting - non seismic | U17: EA | V17: {=INDEX($I$4:$I$444,MATCH(1,($C$4:$C$444=$Q17)*($B$4:$B$444=V$3),0))} -> 337.5 | W17: {=INDEX($I$4:$I$444,MATCH(1,($C$4:$C$444=$Q17)*($B$4:$B$444=W$3),0))} -> 337.5 | X17: {=INDEX($I$4:$I$444,MATCH(1,($C$4:$C$444=$Q17)*($B$4:$B$444=X$3),0))} -> 337.5 | Y17: {=INDEX($I$4:$I$444,MATCH(1,($C$4:$C$444=$Q17)*($B$4:$B$444=Y$3),0))} -> 337.5 | Z17: {=INDEX($I$4:$I$444,MATCH(1,($C$4:$C$444=$Q17)*($B$4:$B$444=Z$3),0))} -> 337.5 | AA17: {=INDEX($I$4:$I$444,MATCH(1,($C$4:$C$444=$Q17)*($B$4:$B$444=AA$3),0))} -> 337.5 | AB17: {=INDEX($I$4:$I$444,MATCH(1,($C$4:$C$444=$Q17)*($B$4:$B$444=AB$3),0))} -> 337.5 | AC17: {=INDEX($I$4:$I$444,MATCH(1,($C$4:$C$444=$Q17)*($B$4:$B$444=AC$3),0))} -> 337.5 | ... AN17: {=INDEX($I$4:$I$444,MATCH(1,($C$4:$C$444=$Q17)*($B$4:$B$444=AN$3),0))} -> 337.5 | AO17: -
B18: 18th | C18: D3041.031a | D18: D3041.031a HVAC Drops / Diffusers in suspended ceilings - No independent safety wires, SDC A or B | E18: 10 EA | F18: -- | G18: 20.25 | H18: NO | I18: 202.5 | J18: EA | L18: =MAX(F18:G18) -> 20.25 | Q18: D4011.021a | R18: D4011.021a Fire Sprinkler Water Piping - Horizontal Mains and Branches - Old Style Victaulic - Thin Wall Steel - No bracing, SDC A or B, PIPING FRAGILITY | S18: D4011.021a Fire Sprinkler Water Piping - Horizontal Mains and Branches - Old Style Victaulic - Thin Wall Steel - No bracing, SDC A or B, PIPING FRAGILITY | T18: =RIGHT(S18,LEN(S18)-FIND(" ",S18)) -> Fire Sprinkler Water Piping - Horizontal Mains and Branches - Old Style Victaulic - Thin Wall Steel - No bracing, SDC A or B, PIPING FRAGILITY | U18: LF | V18: {=INDEX($I$4:$I$444,MATCH(1,($C$4:$C$444=$Q18)*($B$4:$B$444=V$3),0))} -> 4500 | W18: {=INDEX($I$4:$I$444,MATCH(1,($C$4:$C$444=$Q18)*($B$4:$B$444=W$3),0))} -> 4500 | X18: {=INDEX($I$4:$I$444,MATCH(1,($C$4:$C$444=$Q18)*($B$4:$B$444=X$3),0))} -> 4500 | Y18: {=INDEX($I$4:$I$444,MATCH(1,($C$4:$C$444=$Q18)*($B$4:$B$444=Y$3),0))} -> 4500 | Z18: {=INDEX($I$4:$I$444,MATCH(1,($C$4:$C$444=$Q18)*($B$4:$B$444=Z$3),0))} -> 4500 | AA18: {=INDEX($I$4:$I$444,MATCH(1,($C$4:$C$444=$Q18)*($B$4:$B$444=AA$3),0))} -> 4500 | AB18: {=INDEX($I$4:$I$444,MATCH(1,($C$4:$C$444=$Q18)*($B$4:$B$444=AB$3),0))} -> 4500 | AC18: {=INDEX($I$4:$I$444,MATCH(1,($C$4:$C$444=$Q18)*($B$4:$B$444=AC$3),0))} -> 4500 | ... AN18: {=INDEX($I$4:$I$444,MATCH(1,($C$4:$C$444=$Q18)*($B$4:$B$444=AN$3),0))} -> 4050 | AO18: -
B19: 18th | C19: D3041.041a | D19: D3041.041a Variable Air Volume (VAV) box with in-line coil, SDC A or B | E19: 10 EA | F19: -- | G19: 11.25 | H19: NO | I19: 112.5 | J19: EA | L19: =MAX(F19:G19) -> 11.25 | Q19: D4011.031a | R19: D4011.031a Fire Sprinkler Drop Standard Threaded Steel - Dropping into unbraced lay-in tile SOFT ceiling - 6 ft. long drop maximum, SDC A or B | S19: D4011.031a Fire Sprinkler Drop Standard Threaded Steel - Dropping into unbraced lay-in tile SOFT ceiling - 6 ft. long drop maximum, SDC A or B | T19: =RIGHT(S19,LEN(S19)-FIND(" ",S19)) -> Fire Sprinkler Drop Standard Threaded Steel - Dropping into unbraced lay-in tile SOFT ceiling - 6 ft. long drop maximum, SDC A or B | U19: EA | V19: {=INDEX($I$4:$I$444,MATCH(1,($C$4:$C$444=$Q19)*($B$4:$B$444=V$3),0))} -> 202.5 | W19: {=INDEX($I$4:$I$444,MATCH(1,($C$4:$C$444=$Q19)*($B$4:$B$444=W$3),0))} -> 202.5 | X19: {=INDEX($I$4:$I$444,MATCH(1,($C$4:$C$444=$Q19)*($B$4:$B$444=X$3),0))} -> 202.5 | Y19: {=INDEX($I$4:$I$444,MATCH(1,($C$4:$C$444=$Q19)*($B$4:$B$444=Y$3),0))} -> 202.5 | Z19: {=INDEX($I$4:$I$444,MATCH(1,($C$4:$C$444=$Q19)*($B$4:$B$444=Z$3),0))} -> 202.5 | AA19: {=INDEX($I$4:$I$444,MATCH(1,($C$4:$C$444=$Q19)*($B$4:$B$444=AA$3),0))} -> 202.5 | AB19: {=INDEX($I$4:$I$444,MATCH(1,($C$4:$C$444=$Q19)*($B$4:$B$444=AB$3),0))} -> 202.5 | AC19: {=INDEX($I$4:$I$444,MATCH(1,($C$4:$C$444=$Q19)*($B$4:$B$444=AC$3),0))} -> 202.5 | ... AN19: {=INDEX($I$4:$I$444,MATCH(1,($C$4:$C$444=$Q19)*($B$4:$B$444=AN$3),0))} -> 180 | AO19: -
B20: 18th | C20: D3041.041a | D20: D3041.041a Variable Air Volume (VAV) box with in-line coil, SDC A or B | E20: 10 EA | F20: -- | G20: 4.5 | H20: NO | I20: 45 | J20: EA | L20: =MAX(F20:G20) -> 4.5 | Q20: 0 | R20: #N/A | U20: #N/A
B21: 18th | C21: C3034.001 | D21: C3034.001 Independent Pendant Lighting - non seismic | E21: 1 EA | F21: -- | G21: 337.5 | H21: NO | I21: 337.5 | J21: EA | L21: =MAX(F21:G21) -> 337.5 | Q21: C2011.001a | R21: C2011.001a Prefabricated steel stair with steel treads and landings with seismic joints that accommodate drift. | S21: C2011.001a Prefabricated steel stair with steel treads and landings with seismic joints that accommodate drift. | T21: =RIGHT(S21,LEN(S21)-FIND(" ",S21)) -> Prefabricated steel stair with steel treads and landings with seismic joints that accommodate drift. | U21: EA | V21: {=INDEX($I$4:$I$444,MATCH(1,($C$4:$C$444=$Q21)*($B$4:$B$444=V$3),0))} -> 4.5 | W21: {=INDEX($I$4:$I$444,MATCH(1,($C$4:$C$444=$Q21)*($B$4:$B$444=W$3),0))} -> 4.5 | X21: {=INDEX($I$4:$I$444,MATCH(1,($C$4:$C$444=$Q21)*($B$4:$B$444=X$3),0))} -> 4.5 | Y21: {=INDEX($I$4:$I$444,MATCH(1,($C$4:$C$444=$Q21)*($B$4:$B$444=Y$3),0))} -> 4.5 | Z21: {=INDEX($I$4:$I$444,MATCH(1,($C$4:$C$444=$Q21)*($B$4:$B$444=Z$3),0))} -> 4.5 | AA21: {=INDEX($I$4:$I$444,MATCH(1,($C$4:$C$444=$Q21)*($B$4:$B$444=AA$3),0))} -> 4.5 | AB21: {=INDEX($I$4:$I$444,MATCH(1,($C$4:$C$444=$Q21)*($B$4:$B$444=AB$3),0))} -> 4.5 | AC21: {=INDEX($I$4:$I$444,MATCH(1,($C$4:$C$444=$Q21)*($B$4:$B$444=AC$3),0))} -> 4.5 | ... AN21: {=INDEX($I$4:$I$444,MATCH(1,($C$4:$C$444=$Q21)*($B$4:$B$444=AN$3),0))} -> 4.5 | AO21: -
B22: 18th | C22: C3034.001 | D22: C3034.001 Independent Pendant Lighting - non seismic | E22: 1 EA | F22: -- | G22: 337.5 | H22: NO | I22: 337.5 | J22: EA | L22: =MAX(F22:G22) -> 337.5 | Q22: D5012.021a | R22: D5012.021a Low Voltage Switchgear - Capacity: 100 to <350 Amp - Unanchored equipment that is not vibration isolated - Equipment fragility only | S22: D5012.021a Low Voltage Switchgear - Capacity: 100 to <350 Amp - Unanchored equipment that is not vibration isolated - Equipment fragility only | T22: =RIGHT(S22,LEN(S22)-FIND(" ",S22)) -> Low Voltage Switchgear - Capacity: 100 to <350 Amp - Unanchored equipment that is not vibration isolated - Equipment fragility only | U22: AP | V22: {=INDEX($I$4:$I$444,MATCH(1,($C$4:$C$444=$Q22)*($B$4:$B$444=V$3),0))} -> 13.5 | W22: {=INDEX($I$4:$I$444,MATCH(1,($C$4:$C$444=$Q22)*($B$4:$B$444=W$3),0))} -> 13.5 | X22: {=INDEX($I$4:$I$444,MATCH(1,($C$4:$C$444=$Q22)*($B$4:$B$444=X$3),0))} -> 13.5 | Y22: {=INDEX($I$4:$I$444,MATCH(1,($C$4:$C$444=$Q22)*($B$4:$B$444=Y$3),0))} -> 13.5 | Z22: {=INDEX($I$4:$I$444,MATCH(1,($C$4:$C$444=$Q22)*($B$4:$B$444=Z$3),0))} -> 13.5 | AA22: {=INDEX($I$4:$I$444,MATCH(1,($C$4:$C$444=$Q22)*($B$4:$B$444=AA$3),0))} -> 13.5 | AB22: {=INDEX($I$4:$I$444,MATCH(1,($C$4:$C$444=$Q22)*($B$4:$B$444=AB$3),0))} -> 13.5 | AC22: {=INDEX($I$4:$I$444,MATCH(1,($C$4:$C$444=$Q22)*($B$4:$B$444=AC$3),0))} -> 13.5 | ... AN22: {=INDEX($I$4:$I$444,MATCH(1,($C$4:$C$444=$Q22)*($B$4:$B$444=AN$3),0))} -> 13.5 | AO22: -
B23: 18th | C23: D4011.021a | D23: D4011.021a Fire Sprinkler Water Piping - Horizontal Mains and Branches - Old Style Victaulic - Thin Wall Steel - No bracing, SDC A or B, PIPING FRAGILITY | E23: 1000 LF | F23: -- | G23: 4.5 | H23: NO | I23: 4500 | J23: LF | L23: =MAX(F23:G23) -> 4.5 | Q23: D1014.011 | R23: D1014.011 Traction Elevator – Applies to most California Installations 1976 or later, most western states installations 1982 or later and most other U.S installations 1998 or later. | S23: D1014.011 Traction Elevator – Applies to most California Installations 1976 or later, most western states installations 1982 or later and most other U.S installations 1998 or later. | T23: =RIGHT(S23,LEN(S23)-FIND(" ",S23)) -> Traction Elevator – Applies to most California Installations 1976 or later, most western states installations 1982 or later and most other U.S installations 1998 or later. | U23: EA | V23: - | W23: - | X23: - | Y23: - | Z23: - | AA23: - | AB23: - | AC23: - | AD23: - | AE23: - | AF23: - | AG23: - | AH23: - | AI23: - | AJ23: - | AK23: - | AL23: - | AM23: - | AN23: - | AO23: {=INDEX($I$4:$I$444,MATCH(1,($C$4:$C$444=$Q23)*($B$4:$B$444=AO$3),0))} -> 13.59
B24: 18th | C24: D4011.031a | D24: D4011.031a Fire Sprinkler Drop Standard Threaded Steel - Dropping into unbraced lay-in tile SOFT ceiling - 6 ft. long drop maximum, SDC A or B | E24: 100 EA | F24: -- | G24: 2.025 | H24: NO | I24: 202.5 | J24: EA | L24: =MAX(F24:G24) -> 2.025 | Q24: D3031.011a | R24: D3031.011a Chiller - Capacity: < 100 Ton - Unanchored equipment that is not vibration isolated - Equipment fragility only | S24: D3031.011a Chiller - Capacity: < 100 Ton - Unanchored equipment that is not vibration isolated - Equipment fragility only | T24: =RIGHT(S24,LEN(S24)-FIND(" ",S24)) -> Chiller - Capacity: < 100 Ton - Unanchored equipment that is not vibration isolated - Equipment fragility only | U24: TN | V24: - | W24: - | X24: - | Y24: - | Z24: - | AA24: - | AB24: - | AC24: - | AD24: - | AE24: - | AF24: - | AG24: - | AH24: - | AI24: - | AJ24: - | AK24: - | AL24: - | AM24: - | AN24: - | AO24: {=INDEX($I$4:$I$444,MATCH(1,($C$4:$C$444=$Q24)*($B$4:$B$444=AO$3),0))} -> 1154.25
B25: 17th | C25: B2022.001 | D25: B2022.001 Curtain Walls - Generic Midrise Stick-Built Curtain wall, Config: Monolithic, Lamination: Unknown, Glass Type: Unknown, Details: Aspect ratio = 6:5, Other details Unknown | E25: 30 SF | F25: 225 | G25: -- | H25: NO | I25: 6750 | J25: SF | L25: =MAX(F25:G25) -> 225 | Q25: D3031.021a | R25: D3031.021a Cooling Tower - Capacity: < 100 Ton - Unanchored equipment that is not vibration isolated - Equipment fragility only | S25: D3031.021a Cooling Tower - Capacity: < 100 Ton - Unanchored equipment that is not vibration isolated - Equipment fragility only | T25: =RIGHT(S25,LEN(S25)-FIND(" ",S25)) -> Cooling Tower - Capacity: < 100 Ton - Unanchored equipment that is not vibration isolated - Equipment fragility only | U25: TN | V25: - | W25: - | X25: - | Y25: - | Z25: - | AA25: - | AB25: - | AC25: - | AD25: - | AE25: - | AF25: - | AG25: - | AH25: - | AI25: - | AJ25: - | AK25: - | AL25: - | AM25: - | AN25: - | AO25: {=INDEX($I$4:$I$444,MATCH(1,($C$4:$C$444=$Q25)*($B$4:$B$444=AO$3),0))} -> 1154.25
B26: 17th | C26: B3011.011 | D26: B3011.011 Concrete tile roof, tiles secured and compliant with UBC94 | E26: 100 SF | F26: -- | G26: 60.75 | H26: NO | I26: 6075 | J26: SF | L26: =MAX(F26:G26) -> 60.75 | Q26: D3052.011a | R26: D3052.011a Air Handling Unit - Capacity: <5000 CFM - Unanchored equipment that is not vibration isolated - Equipment fragility only | S26: D3052.011a Air Handling Unit - Capacity: <5000 CFM - Unanchored equipment that is not vibration isolated - Equipment fragility only | T26: =RIGHT(S26,LEN(S26)-FIND(" ",S26)) -> Air Handling Unit - Capacity: <5000 CFM - Unanchored equipment that is not vibration isolated - Equipment fragility only | U26: CF | V26: - | W26: - | X26: - | Y26: - | Z26: - | AA26: - | AB26: - | AC26: - | AD26: - | AE26: - | AF26: - | AG26: - | AH26: - | AI26: - | AJ26: - | AK26: - | AL26: - | AM26: - | AN26: - | AO26: {=INDEX($I$4:$I$444,MATCH(1,($C$4:$C$444=$Q26)*($B$4:$B$444=AO$3),0))} -> 283500
B27: 17th | C27: C1011.001a | D27: C1011.001a Wall Partition, Type: Gypsum with metal studs, Full Height, Fixed Below, Fixed Above | E27: 100 LF | F27: 22.5 | G27: -- | H27: NO | I27: 2250 | J27: LF | L27: =MAX(F27:G27) -> 22.5 | Q27: D5012.013a | R27: D5012.013a Motor Control Center - Capacity: all - Unanchored equipment that is not vibration isolated - Equipment fragility only | S27: D5012.013a Motor Control Center - Capacity: all - Unanchored equipment that is not vibration isolated - Equipment fragility only | T27: =RIGHT(S27,LEN(S27)-FIND(" ",S27)) -> Motor Control Center - Capacity: all - Unanchored equipment that is not vibration isolated - Equipment fragility only | U27: EA | V27: - | W27: - | X27: - | Y27: - | Z27: - | AA27: - | AB27: - | AC27: - | AD27: - | AE27: - | AF27: - | AG27: - | AH27: - | AI27: - | AJ27: - | AK27: - | AL27: - | AM27: - | AN27: - | AO27: {=INDEX($I$4:$I$444,MATCH(1,($C$4:$C$444=$Q27)*($B$4:$B$444=AO$3),0))} -> 16.2
B28: 17th | C28: C3011.001a | D28: C3011.001a Wall Partition, Type: Gypsum + Wallpaper, Full Height, Fixed Below, Fixed Above | E28: 100 LF | F28: 1.701 | G28: -- | H28: NO | I28: 170.1 | J28: LF | L28: =MAX(F28:G28) -> 1.701
B29: 17th | C29: C3027.001 | D29: C3027.001 Raised Access Floor, non seismically rated. | E29: 100 SF | F29: -- | G29: 168.75 | H29: NO | I29: 16875 | J29: SF | L29: =MAX(F29:G29) -> 168.75 | Q29: ** Directional component
B30: 17th | C30: C3032.001a | D30: C3032.001a Suspended Ceiling, SDC A,B,C, Area (A): A < 250, Vert support only | E30: 250 SF | F30: -- | G30: 81 | H30: NO | I30: 20250 | J30: SF | L30: =MAX(F30:G30) -> 81
B31: 17th | C31: C3032.001a | D31: C3032.001a Suspended Ceiling, SDC A,B,C, Area (A): A < 250, Vert support only | E31: 250 SF | F31: -- | G31: 4.5 | H31: NO | I31: 1125 | J31: SF | L31: =MAX(F31:G31) -> 4.5
B32: 17th | C32: C3032.001a | D32: C3032.001a Suspended Ceiling, SDC A,B,C, Area (A): A < 250, Vert support only | E32: 250 SF | F32: -- | G32: 2.7 | H32: NO | I32: 675 | J32: SF | L32: =MAX(F32:G32) -> 2.7 | Q32: UNIQUES | V32: Floor Blocks
B33: 17th | C33: C3032.001a | D33: C3032.001a Suspended Ceiling, SDC A,B,C, Area (A): A < 250, Vert support only | E33: 250 SF | F33: -- | G33: 1.8 | H33: NO | I33: 450 | J33: SF | L33: =MAX(F33:G33) -> 1.8 | Q33: ID | R33: Names | S33: Pasted Names | T33: Text Names | U33: Units | V33: 18th | W33: 17th | X33: 16th | Y33: 15th | Z33: 14th | AA33: 13th | AB33: 12th | AC33: 11th | AD33: 10th | AE33: 9th | AF33: 8th | AG33: 7th | AH33: 6th | AI33: 5th | AJ33: 4th | AK33: 3rd | AL33: 2nd | AM33: 1st | AN33: Ground | AO33: ALL
B34: 17th | C34: E2022.112a | D34: E2022.112a Vertical Filing Cabinet, 2 drawer, unanchored laterally | E34: 1 EA | F34: -- | G34: 18 | H34: NO | I34: 18 | J34: EA | L34: =MAX(F34:G34) -> 18 | Q34: {=_xlfn.UNIQUE(C4:C444)} -> B2022.001 | R34: {=VLOOKUP(_xlfn.ANCHORARRAY(Q4),C4:D444,2,FALSE)} -> B2022.001 Curtain Walls - Generic Midrise Stick-Built Curtain wall, Config: Monolithic, Lamination: Unknown, Glass Type: Unknown, Details: Aspect ratio = 6:5, Other details Unknown | S34: B2022.001 Curtain Walls - Generic Midrise Stick-Built Curtain wall, Config: Monolithic, Lamination: Unknown, Glass Type: Unknown, Details: Aspect ratio = 6:5, Other details Unknown | T34: =RIGHT(S34,LEN(S34)-FIND(" ",S34)) -> Curtain Walls - Generic Midrise Stick-Built Curtain wall, Config: Monolithic, Lamination: Unknown, Glass Type: Unknown, Details: Aspect ratio = 6:5, Other details Unknown | U34: {=VLOOKUP(_xlfn.ANCHORARRAY(Q4),C4:J444,8,FALSE)} -> SF | V34: {=INDEX($L$4:$L$444,MATCH(1,($C$4:$C$444=$Q34)*($B$4:$B$444=V$33),0))} -> 225 | W34: {=INDEX($L$4:$L$444,MATCH(1,($C$4:$C$444=$Q34)*($B$4:$B$444=W$33),0))} -> 225 | X34: {=INDEX($L$4:$L$444,MATCH(1,($C$4:$C$444=$Q34)*($B$4:$B$444=X$33),0))} -> 225 | Y34: {=INDEX($L$4:$L$444,MATCH(1,($C$4:$C$444=$Q34)*($B$4:$B$444=Y$33),0))} -> 225 | Z34: {=INDEX($L$4:$L$444,MATCH(1,($C$4:$C$444=$Q34)*($B$4:$B$444=Z$33),0))} -> 225 | AA34: {=INDEX($L$4:$L$444,MATCH(1,($C$4:$C$444=$Q34)*($B$4:$B$444=AA$33),0))} -> 225 | AB34: {=INDEX($L$4:$L$444,MATCH(1,($C$4:$C$444=$Q34)*($B$4:$B$444=AB$33),0))} -> 225 | AC34: {=INDEX($L$4:$L$444,MATCH(1,($C$4:$C$444=$Q34)*($B$4:$B$444=AC$33),0))} -> 225 | ... AN34: {=INDEX($L$4:$L$444,MATCH(1,($C$4:$C$444=$Q34)*($B$4:$B$444=AN$33),0))} -> 45 | AO34: -
B35: 17th | C35: E2022.102a | D35: E2022.102a Bookcase, 2 shelves, unanchored laterally | E35: 1 EA | F35: -- | G35: 45 | H35: NO | I35: 45 | J35: EA | L35: =MAX(F35:G35) -> 45 | O35: {=_xlfn.UNIQUE(B4:B444)} -> 18th | Q35: B3011.011 | R35: B3011.011 Concrete tile roof, tiles secured and compliant with UBC94 | S35: B3011.011 Concrete tile roof, tiles secured and compliant with UBC94 | T35: =RIGHT(S35,LEN(S35)-FIND(" ",S35)) -> Concrete tile roof, tiles secured and compliant with UBC94 | U35: SF | V35: {=INDEX($L$4:$L$444,MATCH(1,($C$4:$C$444=$Q35)*($B$4:$B$444=V$33),0))} -> 60.75 | W35: {=INDEX($L$4:$L$444,MATCH(1,($C$4:$C$444=$Q35)*($B$4:$B$444=W$33),0))} -> 60.75 | X35: {=INDEX($L$4:$L$444,MATCH(1,($C$4:$C$444=$Q35)*($B$4:$B$444=X$33),0))} -> 60.75 | Y35: {=INDEX($L$4:$L$444,MATCH(1,($C$4:$C$444=$Q35)*($B$4:$B$444=Y$33),0))} -> 60.75 | Z35: {=INDEX($L$4:$L$444,MATCH(1,($C$4:$C$444=$Q35)*($B$4:$B$444=Z$33),0))} -> 60.75 | AA35: {=INDEX($L$4:$L$444,MATCH(1,($C$4:$C$444=$Q35)*($B$4:$B$444=AA$33),0))} -> 60.75 | AB35: {=INDEX($L$4:$L$444,MATCH(1,($C$4:$C$444=$Q35)*($B$4:$B$444=AB$33),0))} -> 60.75 | AC35: {=INDEX($L$4:$L$444,MATCH(1,($C$4:$C$444=$Q35)*($B$4:$B$444=AC$33),0))} -> 60.75 | ... AN35: {=INDEX($L$4:$L$444,MATCH(1,($C$4:$C$444=$Q35)*($B$4:$B$444=AN$33),0))} -> 112.5 | AO35: -
